<?xml version="1.0"?>
<robot xmlns:xacro="http://www.ros.org/wiki/xacro" name="myrobot"> 

  <xacro:include filename="$(find robot_description_pkg)/urdf/material.xacro"/>
  <!-- <xacro:include filename="$(find robot_description_pkg)/urdf/plugin.gazebo"/> -->

<link name="base_link"/>

<joint name="chassis_joint" type="fixed">
  <parent link="base_link"/>
  <child link="chassis"/>
  <origin xyz="0 0 0" rpy="0 0 0"/>
  <axis xyz="0 0 0"/>
</joint>
 

  <!-- CHASSIS LINK -->
  <link name="chassis">
        <inertial>
            <origin xyz="0.0 0.0 0.0"/>
            <mass value="20"/>
            <inertia ixx="0.1" ixy="0.0" ixz="0.0" iyy="0.1" iyz="0.0" izz="0.1"/>
        </inertial>
        <visual>
            <origin xyz="0.0 0.0 0.2" />
            <geometry>
                <box size="0.6 0.45 0.15"/>
            </geometry>
            <material name="white"/>
        </visual>
        <collision>
            <origin xyz="0.0 0.0 0.2" rpy="0.0 0.0 0.0"/>
            <geometry>
                <box size="0.6 0.45 0.15"/>
            </geometry>
        </collision>
  </link>
 

  <!-- FRONT LEFT WHEEL LINK   -->
  <link name="front_left_wheel">    
    <inertial>
      <origin rpy="0 0 0 " xyz="0 0 0"/>
      <mass value="0.7"/>
      <inertia ixx="0.1" ixy="0" ixz="0" iyy="0.1" iyz="0" izz="0.1"/>
    </inertial>
    <collision name="front_left_wheel_collision">
      <origin rpy="0 1.5707 1.5707" xyz="0 0 0" />
      <geometry>
        <cylinder length="0.05" radius="0.1"/>
      </geometry>
    </collision>
    <visual name="front_left_wheel_visual">
      <origin rpy="0 1.5707 1.5707" xyz="0 0 0"/>
      <geometry>
        <cylinder length="0.05" radius="0.1"/>
      </geometry>
      <material name="Black"/>      
    </visual>
  </link>
  <joint name="joint_front_left_wheel" type="continuous">
    <origin rpy="0 0 0" xyz="0.175 0.25 0.1"/>
    <child link="front_left_wheel" />
    <parent link="chassis"/>
    <axis rpy="0 0 0" xyz="0 1 0"/>
  </joint>  

  <!-- BACk LEFT WHEEL LINK    -->
  <link name="back_left_wheel">    
    <inertial>
      <mass value="0.7"/>
      <origin rpy="0 0 0" xyz="0 0 0"/>
      <inertia ixx="0.1" ixy="0" ixz="0" iyy="0.1" iyz="0" izz="0.1"/>
    </inertial>
    <collision name="back_left_wheel_collision">
      <origin rpy="0 1.5707 1.5707" xyz="0 0 0" />
      <geometry>
        <cylinder length="0.05" radius="0.1"/>
      </geometry>
    </collision>
    <visual name="back_left_wheel_visual">
      <origin rpy="0 1.5707 1.5707" xyz="0 0 0"/>
      <geometry>
        <cylinder length="0.05" radius="0.1"/>
      </geometry>  
      <material name="Black"/>    
    </visual>   
  </link> 
  <joint name="joint_back_left_wheel" type="continuous">
    <origin rpy="0 0 0" xyz="-0.175 0.25 0.1"/>
    <child link="back_left_wheel" />
    <parent link="chassis"/>
    <axis rpy="0 0 0" xyz="0 1 0"/>
  </joint> 


  <!-- FRONT RIGHT WHEEL LINK   -->
  <link name="front_right_wheel">    
    <inertial>
      <mass value="0.7"/>
      <origin rpy="0 0 0" xyz="0 0 0"/>
      <inertia ixx="0.1" ixy="0" ixz="0" iyy="0.1" iyz="0" izz="0.1"/>
    </inertial>
    <collision name="front_right_wheel_collision">
      <origin rpy="0 1.5707 1.5707" xyz="0 0 0" />
      <geometry>
        <cylinder length="0.05" radius="0.1"/>
      </geometry>
    </collision>
    <visual name="front_right_wheel_visual">
      <origin rpy="0 1.5707 1.5707" xyz="0 0 0"/>
      <geometry>
        <cylinder length="0.05" radius="0.1"/>
      </geometry>   
      <material name="Black"/>   
    </visual>
  </link>
  <joint name="joint_front_right_wheel" type="continuous">
    <origin rpy="0 0 0" xyz="0.175 -0.25 0.10"/>
    <child link="front_right_wheel" />
    <parent link="chassis"/>
    <axis rpy="0 0 0" xyz="0 1 0"/>
  </joint>   

<!-- BACk RIGHT WHEEL LINK    -->
  <link name="back_right_wheel">    
    <inertial>
      <mass value="0.7"/>
      <origin rpy="0 0 0" xyz="0 0 0"/>
      <inertia ixx="0.1" ixy="0" ixz="0" iyy="0.1" iyz="0" izz="0.1"/>
    </inertial>
    <collision name="back_right_wheel_collision">
      <origin rpy="0 1.5707 1.5707" xyz="0 0 0" />
      <geometry>
        <cylinder length="0.05" radius="0.1"/>
      </geometry>
    </collision>
    <visual name="back_right_wheel_visual">
      <origin rpy="0 1.5707 1.5707" xyz="0 0 0"/>
      <geometry>
        <cylinder length="0.05" radius="0.1"/>
      </geometry>  
      <material name="Black"/>    
    </visual>   
  </link> 
  <joint name="joint_back_right_wheel" type="continuous">
    <origin rpy="0 0 0" xyz="-0.175 -0.25 0.10"/>
    <child link="back_right_wheel" />
    <parent link="chassis"/>
    <axis rpy="0 0 0" xyz="0 1 0"/>
  </joint> 



    <!-- CAMERA LINK -->
    <link name="camera">
        <inertial>
            <origin xyz="0.0 0.0 0.0" rpy="0.0 0.0 0.0"/>
            <mass value="0.9"/>
            <inertia ixx="0.1" ixy="0.0" ixz="0.0" iyy="0.1" iyz="0.0" izz="0.1"/>
        </inertial>
        <visual >
            <origin xyz="0.0 0.0 0.0" rpy="0 0 0"/>
            <geometry>
                <box size="0.050 0.20 0.07"/>
            </geometry>
            <material name="Blue"/>
        </visual>
        <collision>
           <origin xyz="0.0 0.0 0.0" rpy="0 0 0"/>
            <geometry>
                <box size="0.050 0.20 0.07"/>
            </geometry>
        </collision>
    </link>
    <joint name="camera_link_joint" type="fixed">
        <origin xyz="0.325 0.0 0.2" rpy="0.0 0.0 0.0"/>
        <parent link="chassis"/>
        <child link="camera"/>
        <axis xyz="0.0 0.0 0.0"/>
    </joint>
   
   <link name="lidar">
    <inertial>
      <origin xyz="0.0 0.0 0.0" rpy="0.0 0.0 0.0"/>
      <mass value="1.0"/>
      <inertia ixx="0.10" ixy="0.0" ixz="0.0" iyy="0.10" iyz="0.0" izz="0.10"/>
    </inertial>
    <visual name="">
      <origin xyz="0.0 0.0 0.0" rpy="0.0 0.0 0.0"/>
      <geometry>
       <box size="0.050 0.050 0.07"/>
      </geometry>
      <material name="">
        <color rgba="1.0 0.0 0.0 1.0"/>
        <texture filename=""/>
      </material>
    </visual>
    <collision>
      <origin xyz="0.0 0.0 0.0" rpy="0.0 0.0 0.0"/>
      <geometry>
        <box size="0.050 0.050 0.07"/>
      </geometry>
    </collision>
   </link>
   <joint name="joint_lidar" type="fixed">
    <origin xyz="0.0 0.0 0.3" rpy="0.0 0.0 0.0"/>
    <parent link="chassis"/>
    <child link="lidar"/>
   </joint>

  <gazebo>
      <plugin name='skid_steer_drive' filename='libgazebo_ros_diff_drive.so'>
        <!-- <ros>
          <remapping>odom:=odom/unfiltered</remapping>
        </ros> -->

        <num_wheel_pairs>2</num_wheel_pairs>

        <left_joint>joint_front_left_wheel</left_joint>
        <right_joint>joint_front_right_wheel</right_joint>
        
        <left_joint>joint_back_left_wheel</left_joint>
        <right_joint>joint_back_right_wheel</right_joint>

        <wheel_separation>0.5</wheel_separation>
        <wheel_separation>0.5</wheel_separation>
        <wheel_diameter>0.2</wheel_diameter>
        <wheel_diameter>0.2</wheel_diameter>

        <updateRate>100</updateRate>
        <max_wheel_acceleration>1.0</max_wheel_acceleration>
        <max_wheel_torque>20</max_wheel_torque>

        <robot_base_frame>base_link</robot_base_frame>
        <publish_odom>true</publish_odom>
        <publish_odom_tf>true</publish_odom_tf>
        <publish_wheel_tf>true</publish_wheel_tf>
        <odometry_frame>odom</odometry_frame>
        <odometry_source>world</odometry_source>
      </plugin>
    </gazebo>
         <!-- LIDER -->
    <gazebo reference="lidar">
        <sensor type="ray" name="head_hokuyo_sensor">
            <pose>0 0 0 0 0 0</pose>
            <visualize>true</visualize>
            <update_rate>40</update_rate>
            <ray>
                <scan>
                    <horizontal>
                        <samples>780</samples>
                        <resolution>1</resolution>
                        <min_angle>-1.570796327</min_angle> 
                        <max_angle>1.570796327</max_angle>
                    </horizontal>
                </scan>
                <range>
                    <min>0.10</min>
                    <max>30.0</max>
                    <resolution>0.01</resolution>
                </range>
                <noise>
                    <type>gaussian</type>
                    <!-- Noise parameters based on published spec for Hokuyo laser
                        achieving "+-30mm" accuracy at range < 10m.  A mean of 0.0m and
                        stddev of 0.01m will put 99.7% of samples within 0.03m of the true
                        reading. -->
                    <mean>0.0</mean>
                    <stddev>0.01</stddev>
                </noise>
            </ray>
            <plugin name="lidar_controller" filename="libgazebo_ros_ray_sensor.so">
                <ros>
                    <remapping>~/out:=scan</remapping>                                                                                                                           
                </ros>
                <output_type>sensor_msgs/LaserScan</output_type>
                <topicName>/scan</topicName>
                <frameName>lidar</frameName>
            </plugin>
        </sensor>
    </gazebo>

</robot>
