<?xml version="1.0" ?>
<sdf version="1.5">
  <model name="my_robot">
    <pose>0.0 0.0 0.0 0.0 0.0 0.0</pose>

    <!-- BASE LINK -->
    <link name="base_link"/>

    <!-- CHASSIS -->
    <link name="chassis">
      <inertial>
      <pose>0.0 0.0 0.2 0 0 0</pose>
        <mass>10</mass>
        <inertia>
          <ixx>0.1</ixx>
          <ixy>0.0</ixy>
          <ixz>0.0</ixz>
          <iyy>0.1</iyy>
          <iyz>0.0</iyz>
          <izz>0.1</izz>
        </inertia>
        <pose>0 0 0 0 0 0</pose>
      </inertial>
      <visual name="chassis_visual">
        <pose>0.0 0.0 0.2 0 0 0</pose>
        <geometry>
          <box>
            <size>0.6 0.45 0.15</size>
          </box>
        </geometry>
        <material>
          <ambient>1 1 1 1</ambient>
        </material>
      </visual>
      <collision name="chassis_collision">
        <pose>0.0 0.0 0.2 0 0 0</pose>
        <geometry>
          <box>
            <size>0.6 0.45 0.15</size>
          </box>
        </geometry>
      </collision>
    </link>

    <joint name="joint_chassis" type="fixed">
      <pose>0 0 0 0 0 0</pose>
      <parent>base_link</parent>
      <child>chassis</child>
      <axis>
        <xyz>0 0 0</xyz>
      </axis>
    </joint>


    <!-- FRONT LEFT WHEEL -->
    <link name="front_left_wheel">
      <pose>0.175 0.25 0.1 0 0 0</pose>
      <inertial>
        <mass>0.7</mass>
        <inertia>
          <ixx>0.1</ixx>
          <ixy>0.0</ixy>
          <ixz>0.0</ixz>
          <iyy>0.1</iyy>
          <iyz>0.0</iyz>
          <izz>0.1</izz>
        </inertia>
      </inertial>
      <collision name="collision">
        <pose>0 0 0 0 1.5707 1.5707</pose>
        <geometry>
          <cylinder>
            <radius>0.1</radius>
            <length>0.05</length>
          </cylinder>
        </geometry>
      </collision>
      <visual name="visual">
        <pose>0 0 0 0 1.5707 1.5707</pose>
        <geometry>
          <cylinder>
            <radius>0.1</radius>
            <length>0.05</length>
          </cylinder>
        </geometry>
        <material>
          <ambient>0 0 0 1</ambient>
        </material>
      </visual>
    </link>
    <joint name="joint_front_left_wheel" type="revolute">
      <!-- <pose>0.175 0.25 0.1 0 0 0</pose> -->
      <pose>0 0 0 0 0 0</pose>
      <parent>chassis</parent>
      <child>front_left_wheel</child>
      <axis>
        <xyz>0 1 0</xyz>
      </axis>
    </joint>

    <!-- BACK LEFT WHEEL -->
    <link name="back_left_wheel">
      <pose>-0.175 0.25 0.1 0 0 0</pose>
      <inertial>
        <mass>0.7</mass>
        <inertia>
          <ixx>0.1</ixx>
          <ixy>0.0</ixy>
          <ixz>0.0</ixz>
          <iyy>0.1</iyy>
          <iyz>0.0</iyz>
          <izz>0.1</izz>
        </inertia>
      </inertial>
      <collision name="collision">
        <pose>0 0 0 0 1.5707 1.5707</pose>
        <geometry>
          <cylinder>
            <radius>0.1</radius>
            <length>0.05</length>
          </cylinder>
        </geometry>
      </collision>
      <visual name="visual">
        <pose>0 0 0 0 1.5707 1.5707</pose>
        <geometry>
          <cylinder>
            <radius>0.1</radius>
            <length>0.05</length>
          </cylinder>
        </geometry>
        <material>
          <ambient>0 0 0 1</ambient>
        </material>
      </visual>
    </link>
    <joint name="joint_back_left_wheel" type="revolute">
      <!-- <pose>-0.175 0.25 0.1 0 0 0</pose> -->
      <pose>0 0 0 0 0 0</pose>
      <parent>chassis</parent>
      <child>back_left_wheel</child>
      <axis>
        <xyz>0 1 0</xyz>
      </axis>
    </joint>

    <!-- FRONT RIGHT WHEEL -->
    <link name="front_right_wheel">
     <pose>0.175 -0.25 0.1 0 0 0</pose>
      <inertial>
        <mass>0.7</mass>
        <inertia>
          <ixx>0.1</ixx>
          <ixy>0.0</ixy>
          <ixz>0.0</ixz>
          <iyy>0.1</iyy>
          <iyz>0.0</iyz>
          <izz>0.1</izz>
        </inertia>
      </inertial>
      <collision name="collision">
        <pose>0 0 0 0 1.5707 1.5707</pose>
        <geometry>
          <cylinder>
            <radius>0.1</radius>
            <length>0.05</length>
          </cylinder>
        </geometry>
      </collision>
      <visual name="visual">
        <pose>0 0 0 0 1.5707 1.5707</pose>
        <geometry>
          <cylinder>
            <radius>0.1</radius>
            <length>0.05</length>
          </cylinder>
        </geometry>
        <material>
          <ambient>0 0 0 1</ambient>
        </material>
      </visual>
    </link>
    <joint name="joint_front_right_wheel" type="revolute">
      <!-- <pose>0.175 -0.25 0.1 0 0 0</pose> -->
      <pose>0 0 0 0 0 0</pose>
      <parent>chassis</parent>
      <child>front_right_wheel</child>
      <axis>
        <xyz>0 1 0</xyz>
      </axis>
    </joint>

    <!-- BACK RIGHT WHEEL -->
    <link name="back_right_wheel">
      <pose>-0.175 -0.25 0.1 0 0 0</pose>
      <inertial> 
        <mass>0.7</mass>
        <inertia>
          <ixx>0.1</ixx>
          <ixy>0.0</ixy>
          <ixz>0.0</ixz>
          <iyy>0.1</iyy>
          <iyz>0.0</iyz>
          <izz>0.1</izz>
        </inertia>
      </inertial>
      <collision name="collision">
        <pose>0 0 0 0 1.5707 1.5707</pose>
        <geometry>
          <cylinder>
            <radius>0.1</radius>
            <length>0.05</length>
          </cylinder>
        </geometry>
      </collision>
      <visual name="visual">
        <pose>0 0 0 0 1.5707 1.5707</pose>
        <geometry>
          <cylinder>
            <radius>0.1</radius>
            <length>0.05</length>
          </cylinder>
        </geometry>
        <material>
          <ambient>0 0 0 1</ambient>
        </material>
      </visual>
    </link>
    <joint name="joint_back_right_wheel" type="revolute">
      <!-- <pose>-0.175 -0.25 0.1 0 0 0</pose> -->
      <pose>0 0 0 0 0 0</pose>
      <parent>chassis</parent>
      <child>back_right_wheel</child>
      <axis>
        <xyz>0 1 0</xyz>
      </axis>
    </joint>
	
	  <!-- camera -->
    <link name="camera">
    <pose>0.325 0.0 0.2 0 -0.3 0.0</pose>
      <inertial>
        <mass>0.07</mass>
        <inertia>
          <ixx>0.1</ixx>
          <ixy>0.0</ixy>
          <ixz>0.0</ixz>
          <iyy>0.1</iyy>
          <iyz>0.0</iyz>
          <izz>0.1</izz>
        </inertia>
      </inertial>
      <collision name="collision">
        <pose>0 0 0 0 0 0</pose>
        <geometry>
          <box>
            <size>0.050 0.20 0.07</size>
          </box>
        </geometry>
      </collision>
      <visual name="visual">
        <pose>0 0 0 0 0 0</pose>
        <geometry>
          <box>
            <size>0.050 0.20 0.07</size>
          </box>
        </geometry>
        <material>
          <ambient>0 0 0 1</ambient>
        </material>
      </visual>
      <sensor name="camera" type="camera">
        <always_on>true</always_on>
        <visualize>true</visualize>
        <update_rate>30</update_rate>
        <camera name="picam">
          <horizontal_fov>1.085595</horizontal_fov>
          <image>
              <width>640</width>
              <height>480</height>
              <format>R8G8B8</format>
          </image>
          <clip>
              <near>0.03</near>
              <far>100</far>
          </clip>
          <noise>
            <type>gaussian</type>
            <!-- Noise is sampled independently per pixel on each frame.
                  That pixel's noise value is added to each of its color
                  channels, which at that point lie in the range [0,1]. -->
            <mean>0.0</mean>
            <stddev>0.007</stddev>
          </noise>
        </camera>
          <plugin name="camera_driver" filename="libgazebo_ros_camera.so">
            <ros>
              <!-- <namespace>test_cam</namespace> -->
              <!-- <remapping>image_raw:=image_demo</remapping> -->
              <!-- <remapping>camera_info:=camera_info_demo</remapping> -->
            </ros>
            <!-- camera_name>omit so it defaults to sensor name</camera_name-->
            <!-- frame_name>omit so it defaults to link name</frameName-->
            <!-- <hack_baseline>0.07</hack_baseline> -->
          </plugin>
      </sensor>
    </link>
    <joint name="joint_camera" type="fixed">
      <pose>0.325 0.0 0.2 0 0 0.2</pose>
      <parent>chassis</parent>
      <child>camera</child>
      <axis>
        <xyz>0 0 0</xyz>
      </axis>
    </joint>
    
    <!-- CAMERA -->


    <!-- lidar -->
    <link name="lidar">
      <pose>0 0 0.3 0 0 0 </pose>
      <inertial>
        <pose>0 0 0 0 0 0 </pose>
        <mass>0.010</mass>
        <inertia>
          <ixx>0.1</ixx>
          <ixy>0.0</ixy>
          <ixz>0.0</ixz>
          <iyy>0.1</iyy>
          <iyz>0.0</iyz>
          <izz>0.1</izz>
        </inertia>
      </inertial>
      <collision name="collision">
        <pose>0 0 0 0 0 0 </pose>
        <geometry>
          <box>
            <size>0.050 0.050 0.07</size>
          </box>
        </geometry>
      </collision>
      <visual name="visual">
        <pose>0 0 0 0 0 0</pose>
        <geometry>
          <box>
            <size>0.050 0.050 0.07</size>
          </box>
        </geometry>
        <material>
          <ambient>0 0 0 1</ambient>
        </material>
      </visual>
      
      <sensor name="lidara" type="ray">
        <pose>0 0 0.0 0 0 0</pose>
        <always_on>true</always_on>
        <visualize>true</visualize>
        <update_rate>5</update_rate>
        <ray>
          <scan>
            <horizontal>
              <samples>360</samples>
              <resolution>1.00000</resolution>
              <min_angle>0.000000</min_angle>
              <max_angle>6.280000</max_angle>
            </horizontal>
          </scan>
          <range>
            <min>0.120000</min>
            <max>3.5</max>
            <resolution>0.015000</resolution>
          </range>
          <noise>
            <type>gaussian</type>
            <mean>0.0</mean>
            <stddev>0.01</stddev>
          </noise>
        </ray>
        <plugin name="turtlebot3_lasersca" filename="libgazebo_ros_ray_sensor.so">
          <ros>
            <remapping>~/out:=scan</remapping>
          </ros>
          <output_type>sensor_msgs/LaserScan</output_type>
          <frame_name>lidar</frame_name>
        </plugin>
      </sensor>
      
    </link>

    <joint name="joint_lidar" type="fixed">
      <pose>0 0 0 0 0 0</pose>
      <parent>chassis</parent>
      <child>lidar</child>
      <axis>
        <xyz>0 0 0</xyz>
      </axis>
    </joint>
    
	  
    <!-- <plugin name='skid_steer_drive' filename='libgazebo_ros_diff_drive.so'>

      <num_wheel_pairs>2</num_wheel_pairs>

      <left_joint>joint_front_left_wheel</left_joint>
      <right_joint>joint_front_right_wheel</right_joint>
      <wheel_separation>0.5</wheel_separation>
      <wheel_diameter>0.2</wheel_diameter>

      <left_joint>joint_back_left_wheel</left_joint>
      <right_joint>joint_back_right_wheel</right_joint>
      <wheel_diameter>0.2</wheel_diameter>
      <wheel_separation>0.5</wheel_separation>

      <updateRate>100</updateRate>
      <max_wheel_acceleration>1.0</max_wheel_acceleration>
      <max_wheel_torque>20</max_wheel_torque>
      <command_topic>cmd_vel</command_topic>

      <robot_base_frame>base_link</robot_base_frame>
      <publish_odom>true</publish_odom>
      <publish_odom_tf>true</publish_odom_tf>
      <publish_wheel_tf>false</publish_wheel_tf>
      <odometry_frame>odom</odometry_frame>
    </plugin>   -->

    <plugin name="wheel_drive_controller" filename="libgazebo_ros_diff_drive.so">

      <!-- wheels -->
      <num_wheel_pairs>2</num_wheel_pairs>
      <left_joint>joint_front_left_wheel</left_joint>
      <left_joint>joint_back_left_wheel</left_joint>
      <right_joint>joint_front_right_wheel</right_joint>
      <right_joint>joint_back_right_wheel</right_joint>

      <!-- kinematics -->
      <wheel_separation>0.5</wheel_separation>
      <wheel_diameter>0.2</wheel_diameter>
      <max_wheel_torque>20.0</max_wheel_torque>
      <max_wheel_acceleration>1.0</max_wheel_acceleration>

      <!-- odometry   
      <odometry_source>world</odometry_source>-->
      <odometry_frame>odom</odometry_frame>
      <odometry_topic>odom</odometry_topic>
      <robot_base_frame>base_link</robot_base_frame>

      <!-- topic & re remappings -->
      <ros>
        <namespace>/</namespace>
        <argument>/cmd_vel:=cmd_vel</argument>
        <argument>/odom:=odom</argument>
      </ros>
      <!-- output -->
      <publish_odom>true</publish_odom>
      <publish_odom_tf>true</publish_odom_tf>
      <publish_wheel_tf>true</publish_wheel_tf>
      <update_rate>100.0</update_rate>
    </plugin>

    <!-- *********************** JOINT STATE PUBLISHER *********************   
  
    <plugin name="basic_mobile_bot_joint_state" filename="libgazebo_ros_joint_state_publisher.so">
      <ros>
        <remapping>~/out:=joint_states</remapping>
      </ros>
      <update_rate>30</update_rate>
      <joint_name>joint_front_left_wheel</joint_name>
      <joint_name>joint_front_right_wheel</joint_name>
      <joint_name>joint_back_left_wheel</joint_name>
      <joint_name>joint_back_right_wheel</joint_name>
    </plugin>    
 -->
     
  </model>
</sdf>

